Submission update exception: can't compare offset-naive and offset-aware datetimes

Internal Server Error: /api/dynamic-forms/submissions/

Traceback (most recent call last):

  File "/Users/ujjwallabh/Desktop/TTDF BY UJJWAL/TTDF-Main/dynamic_form/views.py", line 80, in create

    serializer.is_valid(raise_exception=True)

    ~~~~~~~~~~~~~~~~~~~^^^^^^^^^^^^^^^^^^^^^^

  File "/Users/ujjwallabh/Desktop/TTDF BY UJJWAL/TTDF-Main/venv/lib/python3.13/site-packages/rest_framework/serializers.py", line 223, in is_valid

    self._validated_data = self.run_validation(self.initial_data)

                           ~~~~~~~~~~~~~~~~~~~^^^^^^^^^^^^^^^^^^^

  File "/Users/ujjwallabh/Desktop/TTDF BY UJJWAL/TTDF-Main/venv/lib/python3.13/site-packages/rest_framework/serializers.py", line 445, in run_validation

    value = self.validate(value)

  File "/Users/ujjwallabh/Desktop/TTDF BY UJJWAL/TTDF-Main/dynamic_form/serializers.py", line 49, in validate

    if tpl.start_date and now < tpl.start_date:

                          ^^^^^^^^^^^^^^^^^^^^

TypeError: can't compare offset-naive and offset-aware datetimes
 
During handling of the above exception, another exception occurred:
 
Traceback (most recent call last):

  File "/Users/ujjwallabh/Desktop/TTDF BY UJJWAL/TTDF-Main/venv/lib/python3.13/site-packages/django/core/handlers/exception.py", line 55, in inner

    response = get_response(request)

  File "/Users/ujjwallabh/Desktop/TTDF BY UJJWAL/TTDF-Main/venv/lib/python3.13/site-packages/django/core/handlers/base.py", line 197, in _get_response

    response = wrapped_callback(request, *callback_args, **callback_kwargs)

  File "/Users/ujjwallabh/Desktop/TTDF BY UJJWAL/TTDF-Main/venv/lib/python3.13/site-packages/django/views/decorators/csrf.py", line 65, in _view_wrapper

    return view_func(request, *args, **kwargs)

  File "/Users/ujjwallabh/Desktop/TTDF BY UJJWAL/TTDF-Main/venv/lib/python3.13/site-packages/rest_framework/viewsets.py", line 124, in view

    return self.dispatch(request, *args, **kwargs)

           ~~~~~~~~~~~~~^^^^^^^^^^^^^^^^^^^^^^^^^^

  File "/Users/ujjwallabh/Desktop/TTDF BY UJJWAL/TTDF-Main/venv/lib/python3.13/site-packages/rest_framework/views.py", line 509, in dispatch

    response = self.handle_exception(exc)

  File "/Users/ujjwallabh/Desktop/TTDF BY UJJWAL/TTDF-Main/venv/lib/python3.13/site-packages/rest_framework/views.py", line 469, in handle_exception

    self.raise_uncaught_exception(exc)

    ~~~~~~~~~~~~~~~~~~~~~~~~~~~~~^^^^^

  File "/Users/ujjwallabh/Desktop/TTDF BY UJJWAL/TTDF-Main/venv/lib/python3.13/site-packages/rest_framework/views.py", line 480, in raise_uncaught_exception

    raise exc

  File "/Users/ujjwallabh/Desktop/TTDF BY UJJWAL/TTDF-Main/venv/lib/python3.13/site-packages/rest_framework/views.py", line 506, in dispatch

    response = handler(request, *args, **kwargs)

  File "/opt/homebrew/Cellar/python@3.13/3.13.3/Frameworks/Python.framework/Versions/3.13/lib/python3.13/contextlib.py", line 85, in inner

    return func(*args, **kwds)

  File "/Users/ujjwallabh/Desktop/TTDF BY UJJWAL/TTDF-Main/dynamic_form/views.py", line 85, in create

    {"success": False, "message": "Could not save submission.", "errors": serializer.errors},

                                                                          ^^^^^^^^^^^^^^^^^

  File "/Users/ujjwallabh/Desktop/TTDF BY UJJWAL/TTDF-Main/venv/lib/python3.13/site-packages/rest_framework/serializers.py", line 576, in errors

    ret = super().errors

          ^^^^^^^^^^^^^^

  File "/Users/ujjwallabh/Desktop/TTDF BY UJJWAL/TTDF-Main/venv/lib/python3.13/site-packages/rest_framework/serializers.py", line 260, in errors

    raise AssertionError(msg)

AssertionError: You must call `.is_valid()` before accessing `.errors`.

Internal Server Error: /api/dynamic-forms/submissions/

Traceback (most recent call last):

  File "/Users/ujjwallabh/Desktop/TTDF BY UJJWAL/TTDF-Main/dynamic_form/views.py", line 80, in create

    serializer.is_valid(raise_exception=True)

    ~~~~~~~~~~~~~~~~~~~^^^^^^^^^^^^^^^^^^^^^^

  File "/Users/ujjwallabh/Desktop/TTDF BY UJJWAL/TTDF-Main/venv/lib/python3.13/site-packages/rest_framework/serializers.py", line 223, in is_valid

    self._validated_data = self.run_validation(self.initial_data)

                           ~~~~~~~~~~~~~~~~~~~^^^^^^^^^^^^^^^^^^^

  File "/Users/ujjwallabh/Desktop/TTDF BY UJJWAL/TTDF-Main/venv/lib/python3.13/site-packages/rest_framework/serializers.py", line 445, in run_validation

    value = self.validate(value)

  File "/Users/ujjwallabh/Desktop/TTDF BY UJJWAL/TTDF-Main/dynamic_form/serializers.py", line 49, in validate

    if tpl.start_date and now < tpl.start_date:

                          ^^^^^^^^^^^^^^^^^^^^

TypeError: can't compare offset-naive and offset-aware datetimes
 
During handling of the above exception, another exception occurred:
 
Traceback (most recent call last):

  File "/Users/ujjwallabh/Desktop/TTDF BY UJJWAL/TTDF-Main/venv/lib/python3.13/site-packages/django/core/handlers/exception.py", line 55, in inner

    response = get_response(request)

  File "/Users/ujjwallabh/Desktop/TTDF BY UJJWAL/TTDF-Main/venv/lib/python3.13/site-packages/django/core/handlers/base.py", line 197, in _get_response

    response = wrapped_callback(request, *callback_args, **callback_kwargs)

  File "/Users/ujjwallabh/Desktop/TTDF BY UJJWAL/TTDF-Main/venv/lib/python3.13/site-packages/django/views/decorators/csrf.py", line 65, in _view_wrapper

    return view_func(request, *args, **kwargs)

  File "/Users/ujjwallabh/Desktop/TTDF BY UJJWAL/TTDF-Main/venv/lib/python3.13/site-packages/rest_framework/viewsets.py", line 124, in view

    return self.dispatch(request, *args, **kwargs)

           ~~~~~~~~~~~~~^^^^^^^^^^^^^^^^^^^^^^^^^^

  File "/Users/ujjwallabh/Desktop/TTDF BY UJJWAL/TTDF-Main/venv/lib/python3.13/site-packages/rest_framework/views.py", line 509, in dispatch

    response = self.handle_exception(exc)

  File "/Users/ujjwallabh/Desktop/TTDF BY UJJWAL/TTDF-Main/venv/lib/python3.13/site-packages/rest_framework/views.py", line 469, in handle_exception

    self.raise_uncaught_exception(exc)

    ~~~~~~~~~~~~~~~~~~~~~~~~~~~~~^^^^^

  File "/Users/ujjwallabh/Desktop/TTDF BY UJJWAL/TTDF-Main/venv/lib/python3.13/site-packages/rest_framework/views.py", line 480, in raise_uncaught_exception

    raise exc

  File "/Users/ujjwallabh/Desktop/TTDF BY UJJWAL/TTDF-Main/venv/lib/python3.13/site-packages/rest_framework/views.py", line 506, in dispatch

    response = handler(request, *args, **kwargs)

  File "/opt/homebrew/Cellar/python@3.13/3.13.3/Frameworks/Python.framework/Versions/3.13/lib/python3.13/contextlib.py", line 85, in inner

    return func(*args, **kwds)

  File "/Users/ujjwallabh/Desktop/TTDF BY UJJWAL/TTDF-Main/dynamic_form/views.py", line 85, in create

    {"success": False, "message": "Could not save submission.", "errors": serializer.errors},

                                                                          ^^^^^^^^^^^^^^^^^

  File "/Users/ujjwallabh/Desktop/TTDF BY UJJWAL/TTDF-Main/venv/lib/python3.13/site-packages/rest_framework/serializers.py", line 576, in errors

    ret = super().errors

          ^^^^^^^^^^^^^^

  File "/Users/ujjwallabh/Desktop/TTDF BY UJJWAL/TTDF-Main/venv/lib/python3.13/site-packages/rest_framework/serializers.py", line 260, in errors

    raise AssertionError(msg)

AssertionError: You must call `.is_valid()` before accessing `.errors`.

[06/Jul/2025 17:06:18] "POST /api/dynamic-forms/submissions/ HTTP/1.1" 500 188284

 